
Exception on /admin [GET]
Traceback (most recent call last):
  File "/home/marija8t/project_part2/venv/lib/python3.8/site-packages/flask/app.py", line 1455, in wsgi_app
    response = self.full_dispatch_request()
  File "/home/marija8t/project_part2/venv/lib/python3.8/site-packages/flask/app.py", line 869, in full_dispatch_request
    rv = self.handle_user_exception(e)
  File "/home/marija8t/project_part2/venv/lib/python3.8/site-packages/flask/app.py", line 867, in full_dispatch_request
    rv = self.dispatch_request()
  File "/home/marija8t/project_part2/venv/lib/python3.8/site-packages/flask/app.py", line 852, in dispatch_request
    return self.ensure_sync(self.view_functions[rule.endpoint])(**view_args)
  File "/home/marija8t/project_part2/app.py", line 131, in admin
    return render_template('admin.html', users=users)
  File "/home/marija8t/project_part2/venv/lib/python3.8/site-packages/flask/templating.py", line 152, in render_template
    return _render(app, template, context)
  File "/home/marija8t/project_part2/venv/lib/python3.8/site-packages/flask/templating.py", line 133, in _render
    rv = template.render(context)
  File "/home/marija8t/project_part2/venv/lib/python3.8/site-packages/jinja2/environment.py", line 1301, in render
    self.environment.handle_exception()
  File "/home/marija8t/project_part2/venv/lib/python3.8/site-packages/jinja2/environment.py", line 936, in handle_exception
    raise rewrite_traceback_stack(source=source)
  File "/home/marija8t/project_part2/templates/admin.html", line 1, in top-level template code
    {% extends "layout.html" %}
  File "/home/marija8t/project_part2/templates/layout.html", line 34, in top-level template code
    <h1>Welcome {{session.userinfo.name}}!</h1>
  File "/home/marija8t/project_part2/venv/lib/python3.8/site-packages/jinja2/environment.py", line 485, in getattr
    return getattr(obj, attribute)
jinja2.exceptions.UndefinedError: 'flask.sessions.SecureCookieSession object' has no attribute 'userinfo'
Exception on / [GET]
Traceback (most recent call last):
  File "/home/marija8t/project_part2/venv/lib/python3.8/site-packages/flask/app.py", line 1455, in wsgi_app
    response = self.full_dispatch_request()
  File "/home/marija8t/project_part2/venv/lib/python3.8/site-packages/flask/app.py", line 869, in full_dispatch_request
    rv = self.handle_user_exception(e)
  File "/home/marija8t/project_part2/venv/lib/python3.8/site-packages/flask/app.py", line 867, in full_dispatch_request
    rv = self.dispatch_request()
  File "/home/marija8t/project_part2/venv/lib/python3.8/site-packages/flask/app.py", line 852, in dispatch_request
    return self.ensure_sync(self.view_functions[rule.endpoint])(**view_args)
  File "/home/marija8t/project_part2/app.py", line 198, in home
    return render_template('home.html', news_feed=news_feed, total_pages=total_pages, current_page=page, session=session.get('user'), pretty=json.dumps(session.get('user'), indent=4))
  File "/home/marija8t/project_part2/venv/lib/python3.8/site-packages/flask/templating.py", line 152, in render_template
    return _render(app, template, context)
  File "/home/marija8t/project_part2/venv/lib/python3.8/site-packages/flask/templating.py", line 133, in _render
    rv = template.render(context)
  File "/home/marija8t/project_part2/venv/lib/python3.8/site-packages/jinja2/environment.py", line 1301, in render
    self.environment.handle_exception()
  File "/home/marija8t/project_part2/venv/lib/python3.8/site-packages/jinja2/environment.py", line 936, in handle_exception
    raise rewrite_traceback_stack(source=source)
  File "/home/marija8t/project_part2/templates/home.html", line 1, in top-level template code
    {% extends "layout.html" %}
  File "/home/marija8t/project_part2/templates/layout.html", line 37, in top-level template code
    {% if session['user'].get('admin') %} <!-- Check if user is admin -->
  File "/home/marija8t/project_part2/venv/lib/python3.8/site-packages/jinja2/environment.py", line 485, in getattr
    return getattr(obj, attribute)
jinja2.exceptions.UndefinedError: 'dict object' has no attribute 'user'
Exception on /admin [GET]
Traceback (most recent call last):
  File "/home/marija8t/project_part2/venv/lib/python3.8/site-packages/flask/app.py", line 1455, in wsgi_app
    response = self.full_dispatch_request()
  File "/home/marija8t/project_part2/venv/lib/python3.8/site-packages/flask/app.py", line 869, in full_dispatch_request
    rv = self.handle_user_exception(e)
  File "/home/marija8t/project_part2/venv/lib/python3.8/site-packages/flask/app.py", line 867, in full_dispatch_request
    rv = self.dispatch_request()
  File "/home/marija8t/project_part2/venv/lib/python3.8/site-packages/flask/app.py", line 852, in dispatch_request
    return self.ensure_sync(self.view_functions[rule.endpoint])(**view_args)
  File "/home/marija8t/project_part2/app.py", line 131, in admin
    return render_template('admin.html', users=users)
  File "/home/marija8t/project_part2/venv/lib/python3.8/site-packages/flask/templating.py", line 152, in render_template
    return _render(app, template, context)
  File "/home/marija8t/project_part2/venv/lib/python3.8/site-packages/flask/templating.py", line 133, in _render
    rv = template.render(context)
  File "/home/marija8t/project_part2/venv/lib/python3.8/site-packages/jinja2/environment.py", line 1301, in render
    self.environment.handle_exception()
  File "/home/marija8t/project_part2/venv/lib/python3.8/site-packages/jinja2/environment.py", line 936, in handle_exception
    raise rewrite_traceback_stack(source=source)
  File "/home/marija8t/project_part2/templates/admin.html", line 1, in top-level template code
    {% extends "layout.html" %}
  File "/home/marija8t/project_part2/templates/layout.html", line 34, in top-level template code
    <h1>Welcome {{session.userinfo.name}}!</h1>
  File "/home/marija8t/project_part2/venv/lib/python3.8/site-packages/jinja2/environment.py", line 485, in getattr
    return getattr(obj, attribute)
jinja2.exceptions.UndefinedError: 'flask.sessions.SecureCookieSession object' has no attribute 'userinfo'
Exception on /admin [GET]
Traceback (most recent call last):
  File "/home/marija8t/project_part2/venv/lib/python3.8/site-packages/flask/app.py", line 1455, in wsgi_app
    response = self.full_dispatch_request()
  File "/home/marija8t/project_part2/venv/lib/python3.8/site-packages/flask/app.py", line 869, in full_dispatch_request
    rv = self.handle_user_exception(e)
  File "/home/marija8t/project_part2/venv/lib/python3.8/site-packages/flask/app.py", line 867, in full_dispatch_request
    rv = self.dispatch_request()
  File "/home/marija8t/project_part2/venv/lib/python3.8/site-packages/flask/app.py", line 852, in dispatch_request
    return self.ensure_sync(self.view_functions[rule.endpoint])(**view_args)
  File "/home/marija8t/project_part2/app.py", line 153, in admin
    return render_template('admin.html', users=users)
  File "/home/marija8t/project_part2/venv/lib/python3.8/site-packages/flask/templating.py", line 152, in render_template
    return _render(app, template, context)
  File "/home/marija8t/project_part2/venv/lib/python3.8/site-packages/flask/templating.py", line 133, in _render
    rv = template.render(context)
  File "/home/marija8t/project_part2/venv/lib/python3.8/site-packages/jinja2/environment.py", line 1301, in render
    self.environment.handle_exception()
  File "/home/marija8t/project_part2/venv/lib/python3.8/site-packages/jinja2/environment.py", line 936, in handle_exception
    raise rewrite_traceback_stack(source=source)
  File "/home/marija8t/project_part2/templates/admin.html", line 49, in top-level template code
    <form action="{{ url_for('delete_user', user_id=user.id) }}" method="POST">
  File "/home/marija8t/project_part2/venv/lib/python3.8/site-packages/flask/app.py", line 1071, in url_for
    return self.handle_url_build_error(error, endpoint, values)
  File "/home/marija8t/project_part2/venv/lib/python3.8/site-packages/flask/app.py", line 1060, in url_for
    rv = url_adapter.build(  # type: ignore[union-attr]
  File "/home/marija8t/project_part2/venv/lib/python3.8/site-packages/werkzeug/routing/map.py", line 919, in build
    raise BuildError(endpoint, values, method, self)
werkzeug.routing.exceptions.BuildError: Could not build url for endpoint 'delete_user' with values ['user_id']. Did you mean 'dislike_news_item' instead?
